Workbook
Name a: '190 hl Rouge 3em ét.'!#REF!
Name a: #REF!
Name b: '190 hl Rouge 3em ét.'!#REF!
Name b: #REF!
Name d: '190 hl Rouge 3em ét.'!#REF!
Name d: #REF!
Name E: #REF!

Sheet 275 ROUGE 1er ét.
A1: Creux (cm) | B1: Creux (mm) | C1: Volume (L) | D1: Volume (hL)
A2: 0 | B2: 0 | C2: 27951.03 | D2: =$C2/100 -> 279.5103
A3: =$B3/10 -> 1.0863604 | B3: 10.863604 | C3: 27949.064 | D3: =$C3/100 -> 279.49064
A4: =$B4/10 -> 2.1727208 | B4: 21.727208 | C4: 27947.098 | D4: =$C4/100 -> 279.47098
A5: =$B5/10 -> 3.2590811 | B5: 32.590811 | C5: 27945.132 | D5: =$C5/100 -> 279.45132
A6: =$B6/10 -> 4.3454415 | B6: 43.454415 | C6: 27943.166 | D6: =$C6/100 -> 279.43166
A7: =$B7/10 -> 5.4318019 | B7: 54.318019 | C7: 27941.2 | D7: =$C7/100 -> 279.412
A8: =$B8/10 -> 6.5181623 | B8: 65.181623 | C8: 27939.234 | D8: =$C8/100 -> 279.39234
A9: =$B9/10 -> 7.6045226 | B9: 76.045226 | C9: 27937.268 | D9: =$C9/100 -> 279.37268
A10: =$B10/10 -> 8.690883 | B10: 86.90883 | C10: 27935.302 | D10: =$C10/100 -> 279.35302
A11: =$B11/10 -> 9.7772434 | B11: 97.772434 | C11: 27933.336 | D11: =$C11/100 -> 279.33336
A12: =$B12/10 -> 10.863604 | B12: 108.63604 | C12: 27931.37 | D12: =$C12/100 -> 279.3137
A13: =$B13/10 -> 11.949964 | B13: 119.49964 | C13: 27929.404 | D13: =$C13/100 -> 279.29404
A14: =$B14/10 -> 13.036325 | B14: 130.36325 | C14: 27927.438 | D14: =$C14/100 -> 279.27438
... A328: =$B328/10 -> 354.15348 | B328: 3541.5348 | C328: 10.08 | D328: =$C328/100 -> 0.1008

Sheet 345 ROUGE 2nd ét.
A1: Creux (cm) | B1: Creux (mm) | C1: Volume (L) | D1: Volume (hL)
A2: 0 | B2: 0 | C2: 34535 | D2: =$C2/100 -> 345.35
A3: =$B3/10 -> 1.0863604 | B3: 10.863604 | C3: 34533 | D3: =$C3/100 -> 345.33
A4: =$B4/10 -> 2.1727208 | B4: 21.727208 | C4: 34531 | D4: =$C4/100 -> 345.31
A5: =$B5/10 -> 3.2590811 | B5: 32.590811 | C5: 34529 | D5: =$C5/100 -> 345.29
A6: =$B6/10 -> 4.3454415 | B6: 43.454415 | C6: 34527 | D6: =$C6/100 -> 345.27
A7: =$B7/10 -> 5.4318019 | B7: 54.318019 | C7: 34525 | D7: =$C7/100 -> 345.25
A8: =$B8/10 -> 6.5181623 | B8: 65.181623 | C8: 34523 | D8: =$C8/100 -> 345.23
A9: =$B9/10 -> 7.6045226 | B9: 76.045226 | C9: 34521 | D9: =$C9/100 -> 345.21
A10: =$B10/10 -> 8.690883 | B10: 86.90883 | C10: 34519 | D10: =$C10/100 -> 345.19
A11: =$B11/10 -> 9.7772434 | B11: 97.772434 | C11: 34517 | D11: =$C11/100 -> 345.17
A12: =$B12/10 -> 10.863604 | B12: 108.63604 | C12: 34515 | D12: =$C12/100 -> 345.15
A13: =$B13/10 -> 11.949964 | B13: 119.49964 | C13: 34513.076 | D13: =$C13/100 -> 345.13076
A14: =$B14/10 -> 13.036325 | B14: 130.36325 | C14: 34511.152 | D14: =$C14/100 -> 345.11152
... A602: =$B602/10 -> 651.81623 | B602: 6518.1623 | C602: 0 | D602: =$C602/100 -> 0

Sheet 265 ROUGE 3ème ét.
A1: Creux (cm) | D1: Volume (hL)
A2: 0 | B2: 0 | C2: 26500 | D2: =$C2/100 -> 265
A3: =$B3/10 -> 1 | B3: 10 | C3: 26494.299 | D3: =$C3/100 -> 264.94299
A4: =$B4/10 -> 2 | B4: 20 | C4: 26488.598 | D4: =$C4/100 -> 264.88598
A5: =$B5/10 -> 3 | B5: 30 | C5: 26482.897 | D5: =$C5/100 -> 264.82897
A6: =$B6/10 -> 4 | B6: 40 | C6: 26477.196 | D6: =$C6/100 -> 264.77196
A7: =$B7/10 -> 5 | B7: 50 | C7: 26471.495 | D7: =$C7/100 -> 264.71495
A8: =$B8/10 -> 6 | B8: 60 | C8: 26465.794 | D8: =$C8/100 -> 264.65794
A9: =$B9/10 -> 7 | B9: 70 | C9: 26460.093 | D9: =$C9/100 -> 264.60093
A10: =$B10/10 -> 8 | B10: 80 | C10: 26454.392 | D10: =$C10/100 -> 264.54392
A11: =$B11/10 -> 9 | B11: 90 | C11: 26448.691 | D11: =$C11/100 -> 264.48691
A12: =$B12/10 -> 10 | B12: 100 | C12: 26442.99 | D12: =$C12/100 -> 264.4299
A13: =$B13/10 -> 11 | B13: 110 | C13: 26440.162 | D13: =$C13/100 -> 264.40162
A14: =$B14/10 -> 12 | B14: 120 | C14: 26437.334 | D14: =$C14/100 -> 264.37334
... A280: =$B280/10 -> 278 | B280: 2780 | C280: 6166.862 | D280: =$C280/100 -> 61.66862
A281: =$B281/10 -> 279 | B281: 2790 | C281: 6075.196 | D281: =$C281/100 -> 60.75196 | H281: 2790 | I281: 6075.196 | J281: 2790 | K281: 3270 | L281: 2642.25 | M281: 3270 | N281: 3750 | O281: 732.325
A282: =$B282/10 -> 280 | B282: 2800 | C282: 5983.53 | D282: =$C282/100 -> 59.8353 | H282: 2800 | I282: 5983.53 | J282: 2800 | K282: 3280 | L282: 2586.01 | M282: 3280 | N282: 3760 | O282: 706.606
A283: =$B283/10 -> 281 | B283: 2810 | C283: 5898.997 | D283: =$C283/100 -> 58.98997 | H283: 2810 | I283: 5898.997 | J283: 2810 | K283: 3290 | L283: 2529.77 | M283: 3290 | N283: 3770 | O283: 680.887
A284: =$B284/10 -> 282 | B284: 2820 | C284: 5814.464 | D284: =$C284/100 -> 58.14464 | H284: 2820 | I284: 5814.464 | J284: 2820 | K284: 3300 | L284: 2473.53 | M284: 3300 | N284: 3780 | O284: 655.168
A285: =$B285/10 -> 283 | B285: 2830 | C285: 5729.931 | D285: =$C285/100 -> 57.29931 | H285: 2830 | I285: 5729.931 | J285: 2830 | K285: 3310 | L285: 2423.889 | M285: 3310 | N285: 3790 | O285: 629.449
A286: =$B286/10 -> 284 | B286: 2840 | C286: 5645.398 | D286: =$C286/100 -> 56.45398 | H286: 2840 | I286: 5645.398 | J286: 2840 | K286: 3320 | L286: 2374.248 | M286: 3320 | N286: 3800 | O286: 603.73
A287: =$B287/10 -> 285 | B287: 2850 | C287: 5560.865 | D287: =$C287/100 -> 55.60865 | H287: 2850 | I287: 5560.865 | J287: 2850 | K287: 3330 | L287: 2324.607 | M287: 3330 | N287: 3810 | O287: 583.218
A288: =$B288/10 -> 286 | B288: 2860 | C288: 5476.332 | D288: =$C288/100 -> 54.76332 | H288: 2860 | I288: 5476.332 | J288: 2860 | K288: 3340 | L288: 2274.966 | M288: 3340 | N288: 3820 | O288: 562.706
A289: =$B289/10 -> 287 | B289: 2870 | C289: 5391.799 | D289: =$C289/100 -> 53.91799 | H289: 2870 | I289: 5391.799 | J289: 2870 | K289: 3350 | L289: 2225.325 | M289: 3350 | N289: 3830 | O289: 542.194
A290: =$B290/10 -> 288 | B290: 2880 | C290: 5307.266 | D290: =$C290/100 -> 53.07266 | H290: 2880 | I290: 5307.266 | J290: 2880 | K290: 3360 | L290: 2175.684 | M290: 3360 | N290: 3840 | O290: 521.682
A291: =$B291/10 -> 289 | B291: 2890 | C291: 5222.733 | D291: =$C291/100 -> 52.22733 | H291: 2890 | I291: 5222.733 | J291: 2890 | K291: 3370 | L291: 2126.043 | M291: 3370 | N291: 3850 | O291: 501.17
A292: =$B292/10 -> 290 | B292: 2900 | C292: 5138.2 | D292: =$C292/100 -> 51.382 | H292: 2900 | I292: 5138.2 | J292: 2900 | K292: 3380 | L292: 2076.402 | M292: 3380 | N292: 3860 | O292: 480.658
... A328: =$B328/10 -> 326 | B328: 3260 | C328: 2698.49 | D328: =$C328/100 -> 26.9849 | H328: 3260 | I328: 2698.49 | J328: 3260 | K328: 3740 | L328: 758.044 | M328: 3740 | N328: 4220 | O328: 47.564
A329: =$B329/10 -> 327 | B329: 3270 | C329: 2642.25 | D329: =$C329/100 -> 26.4225
A330: =$B330/10 -> 328 | B330: 3280 | C330: 2586.01 | D330: =$C330/100 -> 25.8601
A331: =$B331/10 -> 329 | B331: 3290 | C331: 2529.77 | D331: =$C331/100 -> 25.2977
A332: =$B332/10 -> 330 | B332: 3300 | C332: 2473.53 | D332: =$C332/100 -> 24.7353
A333: =$B333/10 -> 331 | B333: 3310 | C333: 2423.889 | D333: =$C333/100 -> 24.23889
A334: =$B334/10 -> 332 | B334: 3320 | C334: 2374.248 | D334: =$C334/100 -> 23.74248
A335: =$B335/10 -> 333 | B335: 3330 | C335: 2324.607 | D335: =$C335/100 -> 23.24607
A336: =$B336/10 -> 334 | B336: 3340 | C336: 2274.966 | D336: =$C336/100 -> 22.74966
A337: =$B337/10 -> 335 | B337: 3350 | C337: 2225.325 | D337: =$C337/100 -> 22.25325
A338: =$B338/10 -> 336 | B338: 3360 | C338: 2175.684 | D338: =$C338/100 -> 21.75684
A339: =$B339/10 -> 337 | B339: 3370 | C339: 2126.043 | D339: =$C339/100 -> 21.26043
A340: =$B340/10 -> 338 | B340: 3380 | C340: 2076.402 | D340: =$C340/100 -> 20.76402
...

Sheet 365 hl ROUGE 1er ét.
A1: Hauteur (cm) | B1: Hauteur (mm) | C1: Volume (L) | D1: Volume (hL)
A2: =B2/10 -> 0 | B2: 0 | C2: 36734 | D2: =C2/100 -> 367.34
A3: =B3/10 -> 1.1033779 | B3: 11.033779 | C3: 36732.064 | D3: =C3/100 -> 367.32064
A4: =B4/10 -> 2.2067558 | B4: 22.067558 | C4: 36730.128 | D4: =C4/100 -> 367.30128
A5: =B5/10 -> 3.3101338 | B5: 33.101338 | C5: 36728.192 | D5: =C5/100 -> 367.28192
A6: =B6/10 -> 4.4135117 | B6: 44.135117 | C6: 36726.256 | D6: =C6/100 -> 367.26256
A7: =B7/10 -> 5.5168896 | B7: 55.168896 | C7: 36724.32 | D7: =C7/100 -> 367.2432
A8: =B8/10 -> 6.6202675 | B8: 66.202675 | C8: 36722.384 | D8: =C8/100 -> 367.22384
A9: =B9/10 -> 7.7236454 | B9: 77.236454 | C9: 36720.448 | D9: =C9/100 -> 367.20448
A10: =B10/10 -> 8.8270234 | B10: 88.270234 | C10: 36718.512 | D10: =C10/100 -> 367.18512
A11: =B11/10 -> 9.9304013 | B11: 99.304013 | C11: 36716.576 | D11: =C11/100 -> 367.16576
A12: =B12/10 -> 11.033779 | B12: 110.33779 | C12: 36714.64 | D12: =C12/100 -> 367.1464
A13: =B13/10 -> 12.137157 | B13: 121.37157 | C13: 36712.676 | D13: =C13/100 -> 367.12676
... A326: =B326/10 -> 357.49445 | B326: 3574.9445 | C326: 61 | D326: =C326/100 -> 0.61

Sheet 450hL ROUGE 2nd ét.
A1: Hauteur (cm) | B1: Hauteur (mm) | C1: Volume (L) | D1: Volume (hL)
A2: =$B2/10 -> 0 | B2: 0 | C2: 45638.42 | D2: =$C2/100 -> 456.3842
A3: =$B3/10 -> 1.1325701 | B3: 11.325701 | C3: 45636.457 | D3: =$C3/100 -> 456.36457
A4: =$B4/10 -> 2.2651401 | B4: 22.651401 | C4: 45634.494 | D4: =$C4/100 -> 456.34494
A5: =$B5/10 -> 3.3977102 | B5: 33.977102 | C5: 45632.53 | D5: =$C5/100 -> 456.3253
A6: =$B6/10 -> 4.5302802 | B6: 45.302802 | C6: 45630.567 | D6: =$C6/100 -> 456.30567
A7: =$B7/10 -> 5.6628503 | B7: 56.628503 | C7: 45628.604 | D7: =$C7/100 -> 456.28604
A8: =$B8/10 -> 6.7954203 | B8: 67.954203 | C8: 45626.641 | D8: =$C8/100 -> 456.26641
A9: =$B9/10 -> 7.9279904 | B9: 79.279904 | C9: 45624.678 | D9: =$C9/100 -> 456.24678
A10: =$B10/10 -> 9.0605604 | B10: 90.605604 | C10: 45622.714 | D10: =$C10/100 -> 456.22714
A11: =$B11/10 -> 10.19313 | B11: 101.9313 | C11: 45620.751 | D11: =$C11/100 -> 456.20751
A12: =$B12/10 -> 11.325701 | B12: 113.25701 | C12: 45618.788 | D12: =$C12/100 -> 456.18788
A13: =$B13/10 -> 12.458271 | B13: 124.58271 | C13: 45616.824 | D13: =$C13/100 -> 456.16824
... A602: =$B602/10 -> 679.54203 | B602: 6795.4203 | C602: 0 | D602: =$C602/100 -> 0

Sheet 330 hl Rouge 3em ét.
A1: Creux (cm) | B1: Creux (mm) | C1: Volume (L) | D1: Volume (hL)
A2: =B2/10 -> 0 | B2: 0 | C2: 33339.23 | D2: =C2/100 -> 333.3923
A3: =B3/10 -> 1 | B3: 10 | C3: 33336.397 | D3: =C3/100 -> 333.36397
A4: =B4/10 -> 2 | B4: 20 | C4: 33333.564 | D4: =C4/100 -> 333.33564
A5: =B5/10 -> 3 | B5: 30 | C5: 33330.731 | D5: =C5/100 -> 333.30731
A6: =B6/10 -> 4 | B6: 40 | C6: 33327.898 | D6: =C6/100 -> 333.27898
A7: =B7/10 -> 5 | B7: 50 | C7: 33325.065 | D7: =C7/100 -> 333.25065
A8: =B8/10 -> 6 | B8: 60 | C8: 33322.232 | D8: =C8/100 -> 333.22232
A9: =B9/10 -> 7 | B9: 70 | C9: 33319.399 | D9: =C9/100 -> 333.19399
A10: =B10/10 -> 8 | B10: 80 | C10: 33316.566 | D10: =C10/100 -> 333.16566
A11: =B11/10 -> 9 | B11: 90 | C11: 33313.733 | D11: =C11/100 -> 333.13733
A12: =B12/10 -> 10 | B12: 100 | C12: 33310.9 | D12: =C12/100 -> 333.109
A13: =B13/10 -> 11 | B13: 110 | C13: 33308.067 | D13: =C13/100 -> 333.08067
... A447: =B447/10 -> 445 | B447: 4450 | C447: 0 | D447: =C447/100 -> 0

Sheet 190 hL comp bas ROUGE
A1: Hauteur (cm) | B1: Hauteur (mm) | C1: Volume (L) | D1: Volume (hL)
A2: =$B2/10 -> 0 | B2: 0 | C2: 19031.05 | D2: =$C2/100 -> 190.3105
A3: =$B3/10 -> 1.0946363 | B3: 10.946363 | C3: 19029.086 | D3: =$C3/100 -> 190.29086
A4: =$B4/10 -> 2.1892726 | B4: 21.892726 | C4: 19027.122 | D4: =$C4/100 -> 190.27122
A5: =$B5/10 -> 3.2839088 | B5: 32.839088 | C5: 19025.158 | D5: =$C5/100 -> 190.25158
A6: =$B6/10 -> 4.3785451 | B6: 43.785451 | C6: 19023.194 | D6: =$C6/100 -> 190.23194
A7: =$B7/10 -> 5.4731814 | B7: 54.731814 | C7: 19021.23 | D7: =$C7/100 -> 190.2123
A8: =$B8/10 -> 6.5678177 | B8: 65.678177 | C8: 19019.266 | D8: =$C8/100 -> 190.19266
A9: =$B9/10 -> 7.6624539 | B9: 76.624539 | C9: 19017.302 | D9: =$C9/100 -> 190.17302
A10: =$B10/10 -> 8.7570902 | B10: 87.570902 | C10: 19015.338 | D10: =$C10/100 -> 190.15338
A11: =$B11/10 -> 9.8517265 | B11: 98.517265 | C11: 19013.374 | D11: =$C11/100 -> 190.13374
A12: =$B12/10 -> 10.946363 | B12: 109.46363 | C12: 19011.41 | D12: =$C12/100 -> 190.1141
A13: =$B13/10 -> 12.040999 | B13: 120.40999 | C13: 19009.446 | D13: =$C13/100 -> 190.09446
... A327: =$B327/10 -> 355.75679 | B327: 3557.5679 | C327: 24.75 | D327: =$C327/100 -> 0.2475

Sheet 240 hL comp ROUGE 2nd ét.
A1: Hauteur (cm) | D1: Volume (hL)
A2: =$B2/10 -> 0 | B2: 0 | C2: 24000 | D2: =$C2/100 -> 240
A3: =$B3/10 -> 1.0863604 | B3: 10.863604 | C3: 23998.6 | D3: =$C3/100 -> 239.986
A4: =$B4/10 -> 2.1727208 | B4: 21.727208 | C4: 23997.2 | D4: =$C4/100 -> 239.972
A5: =$B5/10 -> 3.2590811 | B5: 32.590811 | C5: 23995.8 | D5: =$C5/100 -> 239.958
A6: =$B6/10 -> 4.3454415 | B6: 43.454415 | C6: 23994.4 | D6: =$C6/100 -> 239.944
A7: =$B7/10 -> 5.4318019 | B7: 54.318019 | C7: 23993 | D7: =$C7/100 -> 239.93
A8: =$B8/10 -> 6.5181623 | B8: 65.181623 | C8: 23991.6 | D8: =$C8/100 -> 239.916
A9: =$B9/10 -> 7.6045226 | B9: 76.045226 | C9: 23990.2 | D9: =$C9/100 -> 239.902
A10: =$B10/10 -> 8.690883 | B10: 86.90883 | C10: 23988.8 | D10: =$C10/100 -> 239.888
A11: =$B11/10 -> 9.7772434 | B11: 97.772434 | C11: 23987.4 | D11: =$C11/100 -> 239.874
A12: =$B12/10 -> 10.863604 | B12: 108.63604 | C12: 23986 | D12: =$C12/100 -> 239.86
A13: =$B13/10 -> 11.949964 | B13: 119.49964 | C13: 23984.079 | D13: =$C13/100 -> 239.84079
... A572: =$B572/10 -> 619.22542 | B572: 6192.2542 | C572: 0 | D572: =$C572/100 -> 0

Sheet 190 hl Rouge 3em ét.
A1: Creux (cm) | B1: Creux (mm) | C1: Volume (L) | D1: Volume (hL)
A2: 0 | B2: 0 | C2: 19055 | D2: =C2/100 -> 190.55
A3: =B3/10 -> 1 | B3: 10 | C3: 19052.2 | D3: =C3/100 -> 190.522
A4: =B4/10 -> 2 | B4: 20 | C4: 19049.4 | D4: =C4/100 -> 190.494
A5: =B5/10 -> 3 | B5: 30 | C5: 19046.6 | D5: =C5/100 -> 190.466
A6: =B6/10 -> 4 | B6: 40 | C6: 19043.8 | D6: =C6/100 -> 190.438
A7: =B7/10 -> 5 | B7: 50 | C7: 19041 | D7: =C7/100 -> 190.41
A8: =B8/10 -> 6 | B8: 60 | C8: 19038.2 | D8: =C8/100 -> 190.382
A9: =B9/10 -> 7 | B9: 70 | C9: 19035.4 | D9: =C9/100 -> 190.354
A10: =B10/10 -> 8 | B10: 80 | C10: 19032.6 | D10: =C10/100 -> 190.326
A11: =B11/10 -> 9 | B11: 90 | C11: 19029.8 | D11: =C11/100 -> 190.298
A12: =B12/10 -> 10 | B12: 100 | C12: 19027 | D12: =C12/100 -> 190.27
A13: =B13/10 -> 11 | B13: 110 | C13: 19024.2 | D13: =C13/100 -> 190.242
A14: =B14/10 -> 12 | B14: 120 | C14: 19021.4 | D14: =C14/100 -> 190.214
... A441: =B441/10 -> 440 | B441: 4400 | C441: 0 | D441: =C441/100 -> 0

Sheet 625 hL comp bas
A1: Hauteur (cm) | B1: Hauteur (mm) | C1: Volume (L) | D1: Volume (hL)
A2: =$B2/10 -> 0 | B2: 0 | C2: 62620.93 | D2: =$C2/100 -> 626.2093
A3: =$B3/10 -> 1 | B3: 10 | C3: 62618.966 | D3: =$C3/100 -> 626.18966
A4: =$B4/10 -> 2 | B4: 20 | C4: 62617.002 | D4: =$C4/100 -> 626.17002
A5: =$B5/10 -> 3 | B5: 30 | C5: 62615.038 | D5: =$C5/100 -> 626.15038
A6: =$B6/10 -> 4 | B6: 40 | C6: 62613.074 | D6: =$C6/100 -> 626.13074
A7: =$B7/10 -> 5 | B7: 50 | C7: 62611.11 | D7: =$C7/100 -> 626.1111
A8: =$B8/10 -> 6 | B8: 60 | C8: 62609.144 | D8: =$C8/100 -> 626.09144
A9: =$B9/10 -> 7 | B9: 70 | C9: 62607.178 | D9: =$C9/100 -> 626.07178
A10: =$B10/10 -> 8 | B10: 80 | C10: 62605.212 | D10: =$C10/100 -> 626.05212
A11: =$B11/10 -> 9 | B11: 90 | C11: 62603.246 | D11: =$C11/100 -> 626.03246
A12: =$B12/10 -> 10 | B12: 100 | C12: 62601.28 | D12: =$C12/100 -> 626.0128
A13: =$B13/10 -> 11 | B13: 110 | C13: 62599.314 | D13: =$C13/100 -> 625.99314
... A585: =$B585/10 -> 583 | B585: 5830 | C585: 134 | D585: =$C585/100 -> 1.34

Sheet 335 hL comp haut
A1: Hauteur (cm) | B1: Hauteur (mm) | C1: Volume (L) | D1: Volume (hL)
A2: =$B2/10 -> 0 | B2: 0 | C2: 4466 | D2: =$C2/100 -> 44.66
A3: =$B3/10 -> 1 | B3: 10 | C3: 4625 | D3: =$C3/100 -> 46.25
A4: =$B4/10 -> 2 | B4: 20 | C4: 4784 | D4: =$C4/100 -> 47.84
A5: =$B5/10 -> 3 | B5: 30 | C5: 4943 | D5: =$C5/100 -> 49.43
A6: =$B6/10 -> 4 | B6: 40 | C6: 5102 | D6: =$C6/100 -> 51.02
A7: =$B7/10 -> 5 | B7: 50 | C7: 5261 | D7: =$C7/100 -> 52.61
A8: =$B8/10 -> 6 | B8: 60 | C8: 5419 | D8: =$C8/100 -> 54.19
A9: =$B9/10 -> 7 | B9: 70 | C9: 5578 | D9: =$C9/100 -> 55.78
A10: =$B10/10 -> 8 | B10: 80 | C10: 5737 | D10: =$C10/100 -> 57.37
A11: =$B11/10 -> 9 | B11: 90 | C11: 5896 | D11: =$C11/100 -> 58.96
A12: =$B12/10 -> 10 | B12: 100 | C12: 6055 | D12: =$C12/100 -> 60.55
A13: =$B13/10 -> 11 | B13: 110 | C13: 6214 | D13: =$C13/100 -> 62.14
... A253: =$B253/10 -> 251 | B253: 2510 | C253: 34500 | D253: =$C253/100 -> 345

Sheet 300 hL comp haut
A1: Hauteur (cm) | B1: Hauteur (mm) | C1: Volume (L) | D1: Volume (hL)
A2: =B2/10 -> 0 | B2: 0 | C2: 1155 | D2: =C2/100 -> 11.55
A3: =B3/10 -> 1 | B3: 10 | C3: 1217 | D3: =C3/100 -> 12.17
A4: =B4/10 -> 2 | B4: 20 | C4: 1278 | D4: =C4/100 -> 12.78
A5: =B5/10 -> 3 | B5: 30 | C5: 1340 | D5: =C5/100 -> 13.4
A6: =B6/10 -> 4 | B6: 40 | C6: 1401 | D6: =C6/100 -> 14.01
A7: =B7/10 -> 5 | B7: 50 | C7: 1463 | D7: =C7/100 -> 14.63
A8: =B8/10 -> 6 | B8: 60 | C8: 1524 | D8: =C8/100 -> 15.24
A9: =B9/10 -> 7 | B9: 70 | C9: 1586 | D9: =C9/100 -> 15.86
A10: =B10/10 -> 8 | B10: 80 | C10: 1647 | D10: =C10/100 -> 16.47
A11: =B11/10 -> 9 | B11: 90 | C11: 1709 | D11: =C11/100 -> 17.09
A12: =B12/10 -> 10 | B12: 100 | C12: 1770 | D12: =C12/100 -> 17.7
A13: =B13/10 -> 11 | B13: 110 | C13: 1831 | D13: =C13/100 -> 18.31
... A544: =B544/10 -> 542 | B544: 5420 | C544: 30131 | D544: =C544/100 -> 301.31

Sheet 300 hL comp bas
A1: Hauteur (cm) | B1: Hauteur (mm) | C1: Volume (L) | D1: Volume (hL)
A2: =B2/10 -> 0 | B2: 0 | C2: 31100 | D2: =C2/100 -> 311
A3: =B3/10 -> 1 | B3: 10 | C3: 31106.356 | D3: =C3/100 -> 311.06356
A4: =B4/10 -> 2 | B4: 20 | C4: 31112.712 | D4: =C4/100 -> 311.12712
A5: =B5/10 -> 3 | B5: 30 | C5: 31119.068 | D5: =C5/100 -> 311.19068
A6: =B6/10 -> 4 | B6: 40 | C6: 31125.424 | D6: =C6/100 -> 311.25424
A7: =B7/10 -> 5 | B7: 50 | C7: 31131.78 | D7: =C7/100 -> 311.3178
A8: =B8/10 -> 6 | B8: 60 | C8: 31129.822 | D8: =C8/100 -> 311.29822
A9: =B9/10 -> 7 | B9: 70 | C9: 31127.864 | D9: =C9/100 -> 311.27864
A10: =B10/10 -> 8 | B10: 80 | C10: 31125.906 | D10: =C10/100 -> 311.25906
A11: =B11/10 -> 9 | B11: 90 | C11: 31123.948 | D11: =C11/100 -> 311.23948
A12: =B12/10 -> 10 | B12: 100 | C12: 31121.99 | D12: =C12/100 -> 311.2199
A13: =B13/10 -> 11 | B13: 110 | C13: 31120.032 | D13: =C13/100 -> 311.20032
... A585: =B585/10 -> 583 | B585: 5830 | C585: 134 | D585: =C585/100 -> 1.34

Sheet 455 hL comp haut
A1: Hauteur (cm) | B1: Hauteur (mm) | C1: Volume (L) | D1: Volume (hL)
A2: =$B2/10 -> 0 | B2: 0 | C2: 2150 | D2: =$C2/100 -> 21.5
A3: =$B3/10 -> 1 | B3: 10 | C3: 2242 | D3: =$C3/100 -> 22.42
A4: =$B4/10 -> 2 | B4: 20 | C4: 2335 | D4: =$C4/100 -> 23.35
A5: =$B5/10 -> 3 | B5: 30 | C5: 2428 | D5: =$C5/100 -> 24.28
A6: =$B6/10 -> 4 | B6: 40 | C6: 2521 | D6: =$C6/100 -> 25.21
A7: =$B7/10 -> 5 | B7: 50 | C7: 2614 | D7: =$C7/100 -> 26.14
A8: =$B8/10 -> 6 | B8: 60 | C8: 2706 | D8: =$C8/100 -> 27.06
A9: =$B9/10 -> 7 | B9: 70 | C9: 2799 | D9: =$C9/100 -> 27.99
A10: =$B10/10 -> 8 | B10: 80 | C10: 2892 | D10: =$C10/100 -> 28.92
A11: =$B11/10 -> 9 | B11: 90 | C11: 2985 | D11: =$C11/100 -> 29.85
A12: =$B12/10 -> 10 | B12: 100 | C12: 3078 | D12: =$C12/100 -> 30.78
A13: =$B13/10 -> 11 | B13: 110 | C13: 3170 | D13: =$C13/100 -> 31.7
... A544: =$B544/10 -> 542 | B544: 5420 | C544: 46142 | D544: =$C544/100 -> 461.42

Sheet 465 hL comp bas
A1: Hauteur (cm) | B1: Hauteur (mm) | C1: Volume (L) | D1: Volume (hL)
A2: =$B2/10 -> 0 | B2: 0 | C2: 46614 | D2: =$C2/100 -> 466.14
A3: =B3/10 -> 1.0576207 | B3: 10.576207 | C3: 46612.046 | D3: =$C3/100 -> 466.12046
A4: =B4/10 -> 2.1152414 | B4: 21.152414 | C4: 46610.092 | D4: =$C4/100 -> 466.10092
A5: =B5/10 -> 3.172862 | B5: 31.72862 | C5: 46608.138 | D5: =$C5/100 -> 466.08138
A6: =B6/10 -> 4.2304827 | B6: 42.304827 | C6: 46606.184 | D6: =$C6/100 -> 466.06184
A7: =B7/10 -> 5.2881034 | B7: 52.881034 | C7: 46604.23 | D7: =$C7/100 -> 466.0423
A8: =B8/10 -> 6.3457241 | B8: 63.457241 | C8: 46602.266 | D8: =$C8/100 -> 466.02266
A9: =B9/10 -> 7.4033448 | B9: 74.033448 | C9: 46600.302 | D9: =$C9/100 -> 466.00302
A10: =B10/10 -> 8.4609654 | B10: 84.609654 | C10: 46598.338 | D10: =$C10/100 -> 465.98338
A11: =B11/10 -> 9.5185861 | B11: 95.185861 | C11: 46596.374 | D11: =$C11/100 -> 465.96374
A12: =B12/10 -> 10.576207 | B12: 105.76207 | C12: 46594.41 | D12: =$C12/100 -> 465.9441
A13: =B13/10 -> 11.633827 | B13: 116.33827 | C13: 46592.444 | D13: =$C13/100 -> 465.92444
A14: =B14/10 -> 12.691448 | B14: 126.91448 | C14: 46590.478 | D14: =$C14/100 -> 465.90478
... A585: =B585/10 -> 616.59286 | B585: 6165.9286 | C585: 122.28 | D585: =$C585/100 -> 1.2228

Sheet 500 hl sur pied
A1: Hauteur (cm) | B1: Hauteur (mm) | C1: Volume (L) | D1: Volume (hL)
A2: =$B2/10 -> 0 | B2: 0 | C2: 252 | D2: =$C2/100 -> 2.52
A3: =$B3/10 -> 1 | B3: 10 | C3: 313 | D3: =$C3/100 -> 3.13
A4: =$B4/10 -> 2 | B4: 20 | C4: 380 | D4: =$C4/100 -> 3.8
A5: =$B5/10 -> 3 | B5: 30 | C5: 455 | D5: =$C5/100 -> 4.55
A6: =$B6/10 -> 4 | B6: 40 | C6: 535 | D6: =$C6/100 -> 5.35
A7: =$B7/10 -> 5 | B7: 50 | C7: 621 | D7: =$C7/100 -> 6.21
A8: =$B8/10 -> 6 | B8: 60 | C8: 712 | D8: =$C8/100 -> 7.12
A9: =$B9/10 -> 7 | B9: 70 | C9: 808 | D9: =$C9/100 -> 8.08
A10: =$B10/10 -> 8 | B10: 80 | C10: 905 | D10: =$C10/100 -> 9.05
A11: =$B11/10 -> 9 | B11: 90 | C11: 1003 | D11: =$C11/100 -> 10.03
A12: =$B12/10 -> 10 | B12: 100 | C12: 1102 | D12: =$C12/100 -> 11.02
A13: =$B13/10 -> 11 | B13: 110 | C13: 1200 | D13: =$C13/100 -> 12
... A575: =$B575/10 -> 573 | B575: 5730 | C575: 50448 | D575: =$C575/100 -> 504.48
A576: 574 | B576: DEBORDEMENT | C576: 50448 | D576: =$C576/100 -> 504.48

Sheet 1250 hL comp bas
A1: Creux (cm) | B1: Creux (mm) | C1: Volume (L) | D1: Volume (hL)
A2: =B2/10 -> 0 | B2: 0 | C2: 124901.25 | D2: =C2/100 -> 1249.0125
A3: =B3/10 -> 1 | B3: 10 | C3: 124899.29 | D3: =C3/100 -> 1248.9929
A4: =B4/10 -> 2 | B4: 20 | C4: 124897.32 | D4: =C4/100 -> 1248.9732
A5: =B5/10 -> 3 | B5: 30 | C5: 124895.36 | D5: =C5/100 -> 1248.9536
A6: =B6/10 -> 4 | B6: 40 | C6: 124893.39 | D6: =C6/100 -> 1248.9339
A7: =B7/10 -> 5 | B7: 50 | C7: 124891.43 | D7: =C7/100 -> 1248.9143
A8: =B8/10 -> 6 | B8: 60 | C8: 124889.47 | D8: =C8/100 -> 1248.8947
A9: =B9/10 -> 7 | B9: 70 | C9: 124887.5 | D9: =C9/100 -> 1248.875
A10: =B10/10 -> 8 | B10: 80 | C10: 124885.54 | D10: =C10/100 -> 1248.8554
A11: =B11/10 -> 9 | B11: 90 | C11: 124883.57 | D11: =C11/100 -> 1248.8357
A12: =B12/10 -> 10 | B12: 100 | C12: 124881.61 | D12: =C12/100 -> 1248.8161
A13: =B13/10 -> 11 | B13: 110 | C13: 124879.65 | D13: =C13/100 -> 1248.7965
... A873: =B873/10 -> 871 | B873: 8710 | C873: 299.38 | D873: =C873/100 -> 2.9938

Sheet 1250 hL comp bas ISOTHERMES
A1: Creux (cm) | B1: Creux (mm) | C1: Volume (L) | D1: Volume (hL)
A2: =B2/10 -> 0 | B2: 0 | C2: 124730 | D2: =C2/100 -> 1247.3
A3: =B3/10 -> 1.1223262 | B3: 11.223262 | C3: 124728 | D3: =C3/100 -> 1247.28
A4: =B4/10 -> 2.2446525 | B4: 22.446525 | C4: 124726 | D4: =C4/100 -> 1247.26
A5: =B5/10 -> 3.3669787 | B5: 33.669787 | C5: 124724 | D5: =C5/100 -> 1247.24
A6: =B6/10 -> 4.489305 | B6: 44.89305 | C6: 124722 | D6: =C6/100 -> 1247.22
A7: =B7/10 -> 5.6116312 | B7: 56.116312 | C7: 124720 | D7: =C7/100 -> 1247.2
A8: =B8/10 -> 6.7339574 | B8: 67.339574 | C8: 124718 | D8: =C8/100 -> 1247.18
A9: =B9/10 -> 7.8562837 | B9: 78.562837 | C9: 124716 | D9: =C9/100 -> 1247.16
A10: =B10/10 -> 8.9786099 | B10: 89.786099 | C10: 124714 | D10: =C10/100 -> 1247.14
A11: =B11/10 -> 10.100936 | B11: 101.00936 | C11: 124712 | D11: =C11/100 -> 1247.12
A12: =B12/10 -> 11.223262 | B12: 112.23262 | C12: 124710 | D12: =C12/100 -> 1247.1
A13: =B13/10 -> 12.345589 | B13: 123.45589 | C13: 124708.1 | D13: =C13/100 -> 1247.081
... A870: =B870/10 -> 974.17917 | B870: 9741.7917 | C870: 780.98 | D870: =C870/100 -> 7.8098

Sheet 625 hL comp bas ISOTHERMES
A1: Creux (cm) | B1: Creux (mm) | C1: Volume (L) | D1: Volume (hL)
A2: =$B2/10 -> 0 | B2: 0 | C2: 62622.93 | D2: =$C2/100 -> 626.2293
A3: =$B3/10 -> 1.1033779 | B3: 11.033779 | C3: 62620.966 | D3: =$C3/100 -> 626.20966
A4: =$B4/10 -> 2.2067558 | B4: 22.067558 | C4: 62619.002 | D4: =$C4/100 -> 626.19002
A5: =$B5/10 -> 3.3101338 | B5: 33.101338 | C5: 62617.038 | D5: =$C5/100 -> 626.17038
A6: =$B6/10 -> 4.4135117 | B6: 44.135117 | C6: 62615.074 | D6: =$C6/100 -> 626.15074
A7: =$B7/10 -> 5.5168896 | B7: 55.168896 | C7: 62613.11 | D7: =$C7/100 -> 626.1311
A8: =$B8/10 -> 6.6202675 | B8: 66.202675 | C8: 62611.146 | D8: =$C8/100 -> 626.11146
A9: =$B9/10 -> 7.7236454 | B9: 77.236454 | C9: 62609.182 | D9: =$C9/100 -> 626.09182
A10: =$B10/10 -> 8.8270234 | B10: 88.270234 | C10: 62607.218 | D10: =$C10/100 -> 626.07218
A11: =$B11/10 -> 9.9304013 | B11: 99.304013 | C11: 62605.254 | D11: =$C11/100 -> 626.05254
A12: =$B12/10 -> 11.033779 | B12: 110.33779 | C12: 62603.29 | D12: =$C12/100 -> 626.0329
A13: =$B13/10 -> 12.137157 | B13: 121.37157 | C13: 62601.625 | D13: =$C13/100 -> 626.01625
... A584: =$B584/10 -> 642.16595 | B584: 6421.6595 | C584: 200 | D584: =$C584/100 -> 2

Sheet 625 hL comp haut
A1: Hauteur (cm) | B1: Hauteur (mm) | C1: Volume (L) | D1: Volume (hL)
A2: =$B2/10 -> 0 | B2: 0 | C2: 3488 | D2: =$C2/100 -> 34.88
A3: =$B3/10 -> 1 | B3: 10 | C3: 3613 | D3: =$C3/100 -> 36.13
A4: =$B4/10 -> 2 | B4: 20 | C4: 3739 | D4: =$C4/100 -> 37.39
A5: =$B5/10 -> 3 | B5: 30 | C5: 3864 | D5: =$C5/100 -> 38.64
A6: =$B6/10 -> 4 | B6: 40 | C6: 3990 | D6: =$C6/100 -> 39.9
A7: =$B7/10 -> 5 | B7: 50 | C7: 4115 | D7: =$C7/100 -> 41.15
A8: =$B8/10 -> 6 | B8: 60 | C8: 4241 | D8: =$C8/100 -> 42.41
A9: =$B9/10 -> 7 | B9: 70 | C9: 4366 | D9: =$C9/100 -> 43.66
A10: =$B10/10 -> 8 | B10: 80 | C10: 4492 | D10: =$C10/100 -> 44.92
A11: =$B11/10 -> 9 | B11: 90 | C11: 4617 | D11: =$C11/100 -> 46.17
A12: =$B12/10 -> 10 | B12: 100 | C12: 4743 | D12: =$C12/100 -> 47.43
A13: =$B13/10 -> 11 | B13: 110 | C13: 4868 | D13: =$C13/100 -> 48.68
... A424: =$B424/10 -> 422 | B424: 4220 | C424: 56453 | D424: =$C424/100 -> 564.53
A425: =$B425/10 -> 423 | B425: 4230 | C425: 56579 | D425: =$C425/100 -> 565.79 | F425: 5190 | G425: 63260
A426: =$B426/10 -> 424 | B426: 4240 | C426: 56704 | D426: =$C426/100 -> 567.04 | F426: 5200 | G426: 63262
A427: =$B427/10 -> 425 | B427: 4250 | C427: 56830 | D427: =$C427/100 -> 568.3 | F427: 5210 | G427: 63264
A428: =$B428/10 -> 426 | B428: 4260 | C428: 56955 | D428: =$C428/100 -> 569.55 | F428: 5220 | G428: 63266
A429: =$B429/10 -> 427 | B429: 4270 | C429: 57081 | D429: =$C429/100 -> 570.81 | F429: 5230 | G429: 63268
A430: =$B430/10 -> 428 | B430: 4280 | C430: 57206 | D430: =$C430/100 -> 572.06 | F430: 5240 | G430: 63270
A431: =$B431/10 -> 429 | B431: 4290 | C431: 57332 | D431: =$C431/100 -> 573.32 | F431: 5250 | G431: 63272
A432: =$B432/10 -> 430 | B432: 4300 | C432: 57457 | D432: =$C432/100 -> 574.57 | F432: 5260 | G432: 63273
A433: =$B433/10 -> 431 | B433: 4310 | C433: 57583 | D433: =$C433/100 -> 575.83 | F433: 5270 | G433: 63275
A434: =$B434/10 -> 432 | B434: 4320 | C434: 57708 | D434: =$C434/100 -> 577.08 | F434: 5280 | G434: 63277
A435: =$B435/10 -> 433 | B435: 4330 | C435: 57834 | D435: =$C435/100 -> 578.34 | F435: 5290 | G435: 63279
A436: =$B436/10 -> 434 | B436: 4340 | C436: 57959 | D436: =$C436/100 -> 579.59 | F436: 5300 | G436: 63281
... A447: =$B447/10 -> 445 | B447: 4450 | C447: 59340 | D447: =$C447/100 -> 593.4 | F447: 5410 | G447: 63303
A448: =$B448/10 -> 446 | B448: 4460 | C448: 59465 | D448: =$C448/100 -> 594.65 | F448: DEBORDEMENT | G448: 63305
A449: =$B449/10 -> 447 | B449: 4470 | C449: 59591 | D449: =$C449/100 -> 595.91
A450: =$B450/10 -> 448 | B450: 4480 | C450: 59716 | D450: =$C450/100 -> 597.16
A451: =$B451/10 -> 449 | B451: 4490 | C451: 59842 | D451: =$C451/100 -> 598.42
A452: =$B452/10 -> 450 | B452: 4500 | C452: 59967 | D452: =$C452/100 -> 599.67
A453: =$B453/10 -> 451 | B453: 4510 | C453: 60093 | D453: =$C453/100 -> 600.93
A454: =$B454/10 -> 452 | B454: 4520 | C454: 60218 | D454: =$C454/100 -> 602.18
A455: =$B455/10 -> 453 | B455: 4530 | C455: 60344 | D455: =$C455/100 -> 603.44
A456: =$B456/10 -> 454 | B456: 4540 | C456: 60469 | D456: =$C456/100 -> 604.69
A457: =$B457/10 -> 455 | B457: 4550 | C457: 60595 | D457: =$C457/100 -> 605.95
A458: =$B458/10 -> 456 | B458: 4560 | C458: 60717 | D458: =$C458/100 -> 607.17
A459: =$B459/10 -> 457 | B459: 4570 | C459: 60842 | D459: =$C459/100 -> 608.42
A460: =$B460/10 -> 458 | B460: 4580 | C460: 60965 | D460: =$C460/100 -> 609.65
...

Sheet 2415 hL
A1: Hauteur (cm) | B1: Hauteur (mm) | C1: Volume (L) | D1: Volume (hL)
A2: =$B2/10 -> 0 | B2: 0 | C2: 642 | D2: =$C2/100 -> 6.42
A3: =$B3/10 -> 1 | B3: 10 | C3: 797 | D3: =$C3/100 -> 7.97
A4: =$B4/10 -> 2 | B4: 20 | C4: 968 | D4: =$C4/100 -> 9.68
A5: =$B5/10 -> 3 | B5: 30 | C5: 1154 | D5: =$C5/100 -> 11.54
A6: =$B6/10 -> 4 | B6: 40 | C6: 1354 | D6: =$C6/100 -> 13.54
A7: =$B7/10 -> 5 | B7: 50 | C7: 1566 | D7: =$C7/100 -> 15.66
A8: =$B8/10 -> 6 | B8: 60 | C8: 1785 | D8: =$C8/100 -> 17.85
A9: =$B9/10 -> 7 | B9: 70 | C9: 2007 | D9: =$C9/100 -> 20.07
A10: =$B10/10 -> 8 | B10: 80 | C10: 2229 | D10: =$C10/100 -> 22.29
A11: =$B11/10 -> 9 | B11: 90 | C11: 2451 | D11: =$C11/100 -> 24.51
A12: =$B12/10 -> 10 | B12: 100 | C12: 2673 | D12: =$C12/100 -> 26.73
A13: =$B13/10 -> 11 | B13: 110 | C13: 2894 | D13: =$C13/100 -> 28.94
... A1152: =$B1152/10 -> 1150 | B1152: 11500 | C1152: 242257 | D1152: =$C1152/100 -> 2422.57
A1153: 1160 | B1153: DEBORDEMENT | C1153: 242267 | D1153: =$C1153/100 -> 2422.67

Sheet 850 hL
A1: =PI() -> 3.1415927 | B1: Pi | E1: I1-10 | Y1: h | Z1: V | AA1: h pris par le haut
Y2: 670 | Z2: 846.58396 | AA2: 0
Y3: 669 | Z3: 846.58396 | AA3: 1
Y4: 668 | Z4: 846.58396 | AA4: 2
Y5: 667 | Z5: 846.58396 | AA5: 3
Y6: 666 | Z6: 846.58396 | AA6: 4
Y7: 665 | Z7: 846.58396 | AA7: 5
Y8: 664 | Z8: 846.58396 | AA8: 6
Y9: 663 | Z9: 846.58396 | AA9: 7
Y10: 662 | Z10: 846.58396 | AA10: 8
Y11: 661 | Z11: 846.58396 | AA11: 9
Y12: 660 | Z12: 846.58396 | AA12: 10
Y13: 659 | Z13: 846.58396 | AA13: 11
... Y27: 645 | Z27: 846.58396 | AA27: 25
K28: volume Cylindre | L28: hL | Y28: 644 | Z28: =U36+$L$36+$H$36 -> 846.58396 | AA28: 26
K29: =500*$A$1*221.5^2 -> 77066802 | L29: =K29/100000 -> 770.66802 | Y29: 643 | Z29: =U37+$L$36+$H$36 -> 845.07324 | AA29: 27
E30: =94^2+221.5^2 -> 57898.25 | Y30: 642 | Z30: =U38+$L$36+$H$36 -> 843.62295 | AA30: 28
A31: V cone bas | B31: =($A$1*221.5^2*94)/3 -> 4829519.6 | D31: longueur hypothénus | E31: =SQRT(E30) -> 240.62055 | O31: h | P31: 50 | T31: =50^2+221.5^2 -> 51562.25 | V31: h total | W31: =94+500+50 -> 644 | Y31: 641 | Z31: =U39+$L$36+$H$36 -> 842.23184 | AA31: 29
A32: h cone bas | B32: 94 | D32: tangente angle b | E32: =(94/221.5) -> 0.42437923 | O32: V cône haut | P32: =($P$31*$A$1*221.5^2)/3 -> 2568893.4 | S32: longueur hypothénus | T32: =SQRT(T31) -> 227.07323 | Y32: 640 | Z32: =U40+$L$36+$H$36 -> 840.89869 | AA32: 30
A33: V cone bas hL | B33: =B31/100000 -> 48.295196 | D33: tangente angle c | E33: =221.5/94 -> 2.356383 | O33: hL | P33: =P32/100000 -> 25.688934 | S33: tangente angle b | T33: =(50/221.5) -> 0.22573363 | Y33: 639 | Z33: =U41+$L$36+$H$36 -> 839.62226 | AA33: 31
S34: tangente angle c | T34: =221.5/50 -> 4.43 | Y34: 638 | Z34: =U42+$L$36+$H$36 -> 838.40131 | AA34: 32
C35: h | D35: R | F35: Volume des cônes | G35: hL | H35: fois 1,04 pour les 2 hL restant | K35: Cylindre | L35: hL | R35: h | S35: R | T35: V | U35: hL | Y35: 637 | Z35: =U43+$L$36+$H$36 -> 837.23463 | AA35: 33
A36: =B33 -> 48.295196 | C36: 94 | D36: =C36/$E$32 -> 221.5 | F36: =($A$1*D36^2*C36)/3 -> 4829519.6 | G36: =F36/100000 -> 48.295196 | H36: =G36*1.04 -> 50.227004 | J36: 500 | K36: =$A$1*J36*221.5^2 -> 77066802 | L36: =K36/100000 -> 770.66802 | R36: 50 | S36: =R36/$T$33 -> 221.5 | T36: =(R36*$A$1*S36^2)/3 -> 2568893.4 | U36: =T36/100000 -> 25.688934 | Y36: 636 | Z36: =U44+$L$36+$H$36 -> 836.12096 | AA36: 34
A37: 47 | C37: 93 | D37: =C37/$E$32 -> 219.14362 | F37: =($A$1*D37^2*C37)/3 -> 4677019.9 | G37: =F37/100000 -> 46.770199 | H37: =G37*1.04 -> 48.641007 | J37: 499 | K37: =$A$1*J37*221.5^2 -> 76912668 | L37: =K37/100000 -> 769.12668 | R37: 49 | S37: =R37/$T$33 -> 217.07 | T37: =(R37*$A$1*S37^2)/3 -> 2417821.9 | U37: =T37/100000 -> 24.178219 | Y37: 635 | Z37: =U45+$L$36+$H$36 -> 835.05908 | AA37: 35
A38: 46 | C38: 92 | D38: =C38/$E$32 -> 216.78723 | F38: =($A$1*D38^2*C38)/3 -> 4527764.7 | G38: =F38/100000 -> 45.277647 | H38: =G38*1.04 -> 47.088753 | J38: 498 | K38: =$A$1*J38*221.5^2 -> 76758535 | L38: =K38/100000 -> 767.58535 | R38: 48 | S38: =R38/$T$33 -> 212.64 | T38: =(R38*$A$1*S38^2)/3 -> 2272792.5 | U38: =T38/100000 -> 22.727925 | Y38: 634 | Z38: =U46+$L$36+$H$36 -> 834.04776 | AA38: 36
A39: 45 | C39: 91 | D39: =C39/$E$32 -> 214.43085 | F39: =($A$1*D39^2*C39)/3 -> 4381719.3 | G39: =F39/100000 -> 43.817193 | H39: =G39*1.04 -> 45.56988 | J39: 497 | K39: =$A$1*J39*221.5^2 -> 76604401 | L39: =K39/100000 -> 766.04401 | R39: 47 | S39: =R39/$T$33 -> 208.21 | T39: =(R39*$A$1*S39^2)/3 -> 2133681.8 | U39: =T39/100000 -> 21.336818 | Y39: 633 | Z39: =U47+$L$36+$H$36 -> 833.08576 | AA39: 37
A40: 44 | C40: 90 | D40: =C40/$E$32 -> 212.07447 | F40: =($A$1*D40^2*C40)/3 -> 4238848.6 | G40: =F40/100000 -> 42.388486 | H40: =G40*1.04 -> 44.084025 | J40: 496 | K40: =$A$1*J40*221.5^2 -> 76450268 | L40: =K40/100000 -> 764.50268 | R40: 46 | S40: =R40/$T$33 -> 203.78 | T40: =(R40*$A$1*S40^2)/3 -> 2000366.5 | U40: =T40/100000 -> 20.003665 | Y40: 632 | Z40: =U48+$L$36+$H$36 -> 832.17185 | AA40: 38
A41: 43 | C41: 89 | D41: =C41/$E$32 -> 209.71809 | F41: =($A$1*D41^2*C41)/3 -> 4099117.7 | G41: =F41/100000 -> 40.991177 | H41: =G41*1.04 -> 42.630824 | J41: 495 | K41: =$A$1*J41*221.5^2 -> 76296134 | L41: =K41/100000 -> 762.96134 | R41: 45 | S41: =R41/$T$33 -> 199.35 | T41: =(R41*$A$1*S41^2)/3 -> 1872723.3 | U41: =T41/100000 -> 18.727233 | Y41: 631 | Z41: =U49+$L$36+$H$36 -> 831.3048 | AA41: 39
A42: 42 | C42: 88 | D42: =C42/$E$32 -> 207.3617 | F42: =($A$1*D42^2*C42)/3 -> 3962491.9 | G42: =F42/100000 -> 39.624919 | H42: =G42*1.04 -> 41.209916 | J42: 494 | K42: =$A$1*J42*221.5^2 -> 76142000 | L42: =K42/100000 -> 761.42 | R42: 44 | S42: =R42/$T$33 -> 194.92 | T42: =(R42*$A$1*S42^2)/3 -> 1750628.9 | U42: =T42/100000 -> 17.506289 | Y42: 630 | Z42: =U50+$L$36+$H$36 -> 830.48337 | AA42: 40
A43: 41 | C43: 87 | D43: =C43/$E$32 -> 205.00532 | F43: =($A$1*D43^2*C43)/3 -> 3828936.2 | G43: =F43/100000 -> 38.289362 | H43: =G43*1.04 -> 39.820936 | J43: 493 | K43: =$A$1*J43*221.5^2 -> 75987867 | L43: =K43/100000 -> 759.87867 | R43: 43 | S43: =R43/$T$33 -> 190.49 | T43: =(R43*$A$1*S43^2)/3 -> 1633960.1 | U43: =T43/100000 -> 16.339601 | Y43: 629 | Z43: =U51+$L$36+$H$36 -> 829.70633 | AA43: 41
A44: 40 | C44: 86 | D44: =C44/$E$32 -> 202.64894 | F44: =($A$1*D44^2*C44)/3 -> 3698415.7 | G44: =F44/100000 -> 36.984157 | H44: =G44*1.04 -> 38.463523 | J44: 492 | K44: =$A$1*J44*221.5^2 -> 75833733 | L44: =K44/100000 -> 758.33733 | R44: 42 | S44: =R44/$T$33 -> 186.06 | T44: =(R44*$A$1*S44^2)/3 -> 1522593.4 | U44: =T44/100000 -> 15.225934 | Y44: 628 | Z44: =U52+$L$36+$H$36 -> 828.97245 | AA44: 42
A45: 39 | C45: 85 | D45: =C45/$E$32 -> 200.29255 | F45: =($A$1*D45^2*C45)/3 -> 3570895.6 | G45: =F45/100000 -> 35.708956 | H45: =G45*1.04 -> 37.137314 | J45: 491 | K45: =$A$1*J45*221.5^2 -> 75679600 | L45: =K45/100000 -> 756.796 | R45: 41 | S45: =R45/$T$33 -> 181.63 | T45: =(R45*$A$1*S45^2)/3 -> 1416405.6 | U45: =T45/100000 -> 14.164056 | Y45: 627 | Z45: =U53+$L$36+$H$36 -> 828.28049 | AA45: 43
A46: 38 | C46: 84 | D46: =C46/$E$32 -> 197.93617 | F46: =($A$1*D46^2*C46)/3 -> 3446340.9 | G46: =F46/100000 -> 34.463409 | H46: =G46*1.04 -> 35.841945 | J46: 490 | K46: =$A$1*J46*221.5^2 -> 75525466 | L46: =K46/100000 -> 755.25466 | R46: 40 | S46: =R46/$T$33 -> 177.2 | T46: =(R46*$A$1*S46^2)/3 -> 1315273.4 | U46: =T46/100000 -> 13.152734 | Y46: 626 | Z46: =U54+$L$36+$H$36 -> 827.62922 | AA46: 44
A47: 37 | C47: 83 | D47: =C47/$E$32 -> 195.57979 | F47: =($A$1*D47^2*C47)/3 -> 3324716.7 | G47: =F47/100000 -> 33.247167 | H47: =G47*1.04 -> 34.577054 | J47: 489 | K47: =$A$1*J47*221.5^2 -> 75371332 | L47: =K47/100000 -> 753.71332 | R47: 39 | S47: =R47/$T$33 -> 172.77 | T47: =(R47*$A$1*S47^2)/3 -> 1219073.5 | U47: =T47/100000 -> 12.190735 | Y47: 625 | Z47: =U55+$L$36+$H$36 -> 827.01742 | AA47: 45
A48: 36 | C48: 82 | D48: =C48/$E$32 -> 193.2234 | F48: =($A$1*D48^2*C48)/3 -> 3205988.3 | G48: =F48/100000 -> 32.059883 | H48: =G48*1.04 -> 33.342278 | J48: 488 | K48: =$A$1*J48*221.5^2 -> 75217199 | L48: =K48/100000 -> 752.17199 | R48: 38 | S48: =R48/$T$33 -> 168.34 | T48: =(R48*$A$1*S48^2)/3 -> 1127682.6 | U48: =T48/100000 -> 11.276826 | Y48: 624 | Z48: =U56+$L$36+$H$36 -> 826.44383 | AA48: 46
... A79: 5 | C79: 51 | D79: =C79/$E$32 -> 120.17553 | F79: =($A$1*D79^2*C79)/3 -> 771313.44 | G79: =F79/100000 -> 7.7131344 | H79: =G79*1.04 -> 8.0216598 | J79: 457 | K79: =$A$1*J79*221.5^2 -> 70439057 | L79: =K79/100000 -> 704.39057 | R79: 7 | S79: =R79/$T$33 -> 31.01 | T79: =(R79*$A$1*S79^2)/3 -> 7049.0435 | U79: =T79/100000 -> 0.070490435 | Y79: 593 | Z79: =U87+$L$36+$H$36 -> 820.89502 | AA79: 77
A80: 4 | C80: 50 | D80: =C80/$E$32 -> 117.81915 | F80: =($A$1*D80^2*C80)/3 -> 726825.88 | G80: =F80/100000 -> 7.2682588 | H80: =G80*1.04 -> 7.5589892 | J80: 456 | K80: =$A$1*J80*221.5^2 -> 70284924 | L80: =K80/100000 -> 702.84924 | R80: 6 | S80: =R80/$T$33 -> 26.58 | T80: =(R80*$A$1*S80^2)/3 -> 4439.0478 | U80: =T80/100000 -> 0.044390478 | Y80: 592 | Z80: =L36+$H$36 -> 820.89502 | AA80: 78
A81: 3 | C81: 49 | D81: =C81/$E$32 -> 115.46277 | F81: =($A$1*D81^2*C81)/3 -> 684082.71 | G81: =F81/100000 -> 6.8408271 | H81: =G81*1.04 -> 7.1144602 | J81: 455 | K81: =$A$1*J81*221.5^2 -> 70130790 | L81: =K81/100000 -> 701.3079 | R81: 5 | S81: =R81/$T$33 -> 22.15 | T81: =(R81*$A$1*S81^2)/3 -> 2568.8934 | U81: =T81/100000 -> 0.025688934 | Y81: 591 | Z81: =L37+$H$36 -> 819.35369 | AA81: 79
A82: 2 | C82: 48 | D82: =C82/$E$32 -> 113.10638 | F82: =($A$1*D82^2*C82)/3 -> 643049.02 | G82: =F82/100000 -> 6.4304902 | H82: =G82*1.04 -> 6.6877099 | J82: 454 | K82: =$A$1*J82*221.5^2 -> 69976656 | L82: =K82/100000 -> 699.76656 | R82: 4 | S82: =R82/$T$33 -> 17.72 | T82: =(R82*$A$1*S82^2)/3 -> 1315.2734 | U82: =T82/100000 -> 0.013152734 | Y82: 590 | Z82: =L38+$H$36 -> 817.81235 | AA82: 80
A83: 1 | C83: 47 | D83: =C83/$E$32 -> 110.75 | F83: =($A$1*D83^2*C83)/3 -> 603689.95 | G83: =F83/100000 -> 6.0368995 | H83: =G83*1.04 -> 6.2783755 | J83: 453 | K83: =$A$1*J83*221.5^2 -> 69822523 | L83: =K83/100000 -> 698.22523 | R83: 3 | S83: =R83/$T$33 -> 13.29 | T83: =(R83*$A$1*S83^2)/3 -> 554.88098 | U83: =T83/100000 -> 0.0055488098 | Y83: 589 | Z83: =L39+$H$36 -> 816.27102 | AA83: 81
...

Sheet Grille
A1: Marseillan | B1: Travée | C1: Niveau | D1: Cuve | E1: Hauteur totale (cm) | F1: Hauteur cachée (cm) | G1: Volume métrique (hl/cm) | H1: Hauteur cheminée (cm) | I1: H mesurable (cm) | J1: Creux (cm) | K1: Volume (hL) | L1: Volume total nominal (hL) | M1: Type de mesure | N1: Volume réel total (hL)
A2: Marseillan Ville | B2: Travée A | C2: 1 | D2: A1-0 | E2: =309+17 -> 326 | G2: =L2/E2 -> 0.33435583 | J2: 244 | K2: =(E2-J2)*G2 -> 27.417178 | L2: 109 | M2: Creux + Cheminée | N2: 109
A3: Marseillan Ville | B3: Travée A | C3: 1 | D3: A1-1 | E3: 579 | J3: 140 | K3: =LOOKUP($J3,'300 hL comp bas'!$A$2:$A$585,'300 hL comp bas'!$D$2:$D$585) -> 273.1379 | L3: 300 | M3: Creux + Cheminée | N3: 311.4
A4: Marseillan Ville | B4: Travée A | C4: 1 | D4: A1-2 | E4: 579 | J4: 336 | K4: =LOOKUP($J4,'300 hL comp bas'!$A$2:$A$585,'300 hL comp bas'!$D$2:$D$585) -> 152.66506 | L4: 300 | M4: Creux + Cheminée | N4: 311.42
A5: Marseillan Ville | B5: Travée A | C5: 1 | D5: A1-3 | E5: 579 | J5: 184 | K5: =LOOKUP($J5,'465 hL comp bas'!$A$2:$A$585,'465 hL comp bas'!$D$2:$D$585) -> 380.89477 | L5: 465 | M5: Creux + Cheminée | N5: 466.14
A6: Marseillan Ville | B6: Travée A | C6: 1 | D6: A1-4 | E6: 579 | J6: 500 | K6: =LOOKUP($J6,'465 hL comp bas'!$A$2:$A$585,'465 hL comp bas'!$D$2:$D$585) -> 103.40531 | L6: 465 | M6: Creux + Cheminée | N6: 466.14
A7: Marseillan Ville | B7: Travée A | C7: 1 | D7: A1-5 | E7: 579 | J7: 150 | K7: =LOOKUP($J7,'625 hL comp bas'!$A$2:$A$581,'625 hL comp bas'!$D$2:$D$581) -> 542.9225 | L7: 625 | M7: Creux + Cheminée | N7: 626.21
A8: Marseillan Ville | B8: Travée A | C8: 1 | D8: A1-6 | E8: 579 | J8: 238 | K8: =LOOKUP($J8,'625 hL comp bas'!$A$2:$A$581,'625 hL comp bas'!$D$2:$D$581) -> 432.4825 | L8: 625 | M8: Creux + Cheminée | N8: 626.21
A9: Marseillan Ville | B9: Travée A | C9: 1 | D9: A1-7 | E9: 880 | J9: 160 | K9: =LOOKUP($J9,'1250 hL comp bas'!$A$2:$A$873,'1250 hL comp bas'!$D$2:$D$873) -> 1130.8677 | L9: 1250 | M9: Creux + Cheminée | N9: 1248.73
A10: Marseillan Ville | B10: Travée A | C10: 1 | D10: A1-8 | E10: 880 | J10: 89 | K10: =LOOKUP($J10,'1250 hL comp bas'!$A$2:$A$873,'1250 hL comp bas'!$D$2:$D$873) -> 1238.1806 | L10: 1250 | M10: Creux + Cheminée | N10: 1248.73
A11: Marseillan Ville | B11: Travée A | C11: 1 | D11: A1-9 | E11: 1160 | J11: 180 | K11: =LOOKUP($E11-$J11,'2415 hL'!$A$2:$A$1153,'2415 hL'!$D$2:$D$1153) -> 2178.86 | L11: 2415 | M11: Creux + Cheminée | N11: 2422.67
A12: Marseillan Ville | B12: Travée A | C12: 1 | D12: A1-10 | E12: 1160 | J12: 45 | K12: =LOOKUP($E12-$J12,'2415 hL'!$A$2:$A$1153,'2415 hL'!$D$2:$D$1153) -> 2419.87 | L12: 2415 | M12: Creux + Cheminée | N12: 2422.67
A13: Marseillan Ville | B13: Travée A | C13: 2 | D13: A2-1 | E13: 542 | J13: 92 | K13: =LOOKUP($E13-$J13,'300 hL comp haut'!$A$2:$A$544,'300 hL comp haut'!$D$2:$D$544) -> 288.17 | L13: 300 | M13: Creux + Cheminée | N13: 301.31
A14: Marseillan Ville | B14: Travée A | C14: 2 | D14: A2-2 | E14: 542 | J14: 67 | K14: =LOOKUP($E14-$J14,'300 hL comp haut'!$A$2:$A$544,'300 hL comp haut'!$D$2:$D$544) -> 299.1 | L14: 300 | M14: Creux + Cheminée | N14: 301.31
A15: Marseillan Ville | B15: Travée A | C15: 2 | D15: A2-3 | E15: 542 | J15: 120 | K15: =LOOKUP($E15-$J15,'455 hL comp haut'!$A$2:$A$544,'455 hL comp haut'!$D$2:$D$544) -> 413.15 | L15: 455 | M15: Creux + Cheminée | N15: 461.42
A16: Marseillan Ville | B16: Travée A | C16: 2 | D16: A2-4 | E16: 542 | J16: 229 | K16: =LOOKUP($E16-$J16,'455 hL comp haut'!$A$2:$A$544,'455 hL comp haut'!$D$2:$D$544) -> 311.99 | L16: 455 | M16: Creux + Cheminée | N16: 461.42
A17: Marseillan Ville | B17: Travée A | C17: 2 | D17: A2-5 | E17: 542 | J17: 92 | K17: =LOOKUP($E17-$J17,'625 hL comp haut'!$A$2:$A$544,'625 hL comp haut'!$D$2:$D$544) -> 599.67 | L17: 625 | M17: Creux + Cheminée | N17: 633.05
A18: Marseillan Ville | B18: Travée A | C18: 2 | D18: A2-6 | E18: 542 | J18: 60 | K18: =LOOKUP($E18-$J18,'625 hL comp haut'!$A$2:$A$544,'625 hL comp haut'!$D$2:$D$544) -> 628.07 | L18: 625 | M18: Creux + Cheminée | N18: 633.05
A19: Marseillan Ville | B19: Travée A | C19: 2 | D19: A2-7 | E19: 251 | J19: 110 | K19: =LOOKUP($E19-$J19,'335 hL comp haut'!$A$2:$A$253,'335 hL comp haut'!$D$2:$D$253) -> 268.67 | L19: 335 | M19: Creux + Cheminée | N19: 345
A20: Marseillan Ville | B20: Travée A | C20: 2 | D20: A2-8 | E20: 251 | J20: 88 | K20: =LOOKUP($E20-$J20,'335 hL comp haut'!$A$2:$A$253,'335 hL comp haut'!$D$2:$D$253) -> 303.62 | L20: 335 | M20: Creux + Cheminée | N20: 345
A21: Marseillan Ville | B21: Travée B | C21: 1 | D21: B1-0 | E21: 520 | G21: =L21/E21 -> 1.6346154 | H21: 60 | J21: 200 | K21: =IF(J21<60,"",(H21+E21-J21)*G21) -> 621.15385 | L21: 850 | M21: Creux + Cheminée | N21: 850
A22: Marseillan Ville | B22: Travée B | C22: 1 | D22: B1-1 | E22: 579 | J22: 308 | K22: =LOOKUP($J22,'300 hL comp bas'!$A$2:$A$585,'300 hL comp bas'!$D$2:$D$585) -> 169.87535 | L22: 300 | M22: Creux + Cheminée | N22: 311.42
A23: Marseillan Ville | B23: Travée B | C23: 1 | D23: B1-2 | E23: 579 | J23: 106 | K23: =LOOKUP($J23,'300 hL comp bas'!$A$2:$A$585,'300 hL comp bas'!$D$2:$D$585) -> 294.2852 | L23: 300 | M23: Creux + Cheminée | N23: 311.42
A24: Marseillan Ville | B24: Travée B | C24: 1 | D24: B1-3 | E24: 579 | J24: 160 | K24: =LOOKUP($J24,'465 hL comp bas'!$A$2:$A$585,'465 hL comp bas'!$D$2:$D$585) -> 401.31205 | L24: 465 | M24: Creux + Cheminée | N24: 466.14
A25: Marseillan Ville | B25: Travée B | C25: 1 | D25: B1-4 | E25: 579 | J25: 380 | K25: =LOOKUP($J25,'465 hL comp bas'!$A$2:$A$585,'465 hL comp bas'!$D$2:$D$585) -> 208.27591 | L25: 465 | M25: Creux + Cheminée | N25: 466.14
A26: Marseillan Ville | B26: Travée B | C26: 1 | D26: B1-5 | E26: 579 | J26: 120 | K26: =LOOKUP($J26,'625 hL comp bas'!$A$2:$A$581,'625 hL comp bas'!$D$2:$D$581) -> 580.6557 | L26: 625 | M26: Creux + Cheminée | N26: 626.21
A27: Marseillan Ville | B27: Travée B | C27: 1 | D27: B1-6 | E27: 579 | J27: 105 | K27: =LOOKUP($J27,'625 hL comp bas'!$A$2:$A$581,'625 hL comp bas'!$D$2:$D$581) -> 599.628 | L27: 625 | M27: Creux + Cheminée | N27: 626.21
A28: Marseillan Ville | B28: Travée B | C28: 1 | D28: B1-7 | E28: 880 | J28: 205 | K28: =LOOKUP($J28,'1250 hL comp bas ISOTHERMES'!$A$2:$A$873,'1250 hL comp bas ISOTHERMES'!$D$2:$D$873) -> 1095.8278 | L28: 1250 | M28: Creux + Cheminée | N28: 1248.73
A29: Marseillan Ville | B29: Travée B | C29: 1 | D29: B1-8 | E29: 880 | J29: 156 | K29: =LOOKUP($J29,'1250 hL comp bas ISOTHERMES'!$A$2:$A$873,'1250 hL comp bas ISOTHERMES'!$D$2:$D$873) -> 1165.6254 | L29: 1250 | M29: Creux + Cheminée | N29: 1248.73
A30: Marseillan Ville | B30: Travée B | C30: 1 | D30: B1-9 | E30: 1160 | J30: 230 | K30: =LOOKUP($E30-$J30,'2415 hL'!$A$2:$A$1153,'2415 hL'!$D$2:$D$1153) -> 2067.93 | L30: 2415 | M30: Creux + Cheminée | N30: 2422.67
A31: Marseillan Ville | B31: Travée B | C31: 1 | D31: B1-10 | E31: 1160 | J31: 270 | K31: =LOOKUP($E31-$J31,'2415 hL'!A31:A1182,'2415 hL'!D31:D1182) -> 1979.18 | L31: 2415 | M31: Creux + Cheminée | N31: 2422.67
A32: Marseillan Ville | B32: Travée B | C32: 2 | D32: B2-1 | E32: 542 | J32: 10 | K32: =LOOKUP($E32-$J32,'300 hL comp haut'!$A$2:$A$544,'300 hL comp haut'!$D$2:$D$544) -> 301.12 | L32: 300 | M32: Creux + Cheminée | N32: 301.31
A33: Marseillan Ville | B33: Travée B | C33: 2 | D33: B2-2 | E33: 542 | J33: 127 | K33: =LOOKUP($E33-$J33,'300 hL comp haut'!$A$2:$A$544,'300 hL comp haut'!$D$2:$D$544) -> 266.65 | L33: 300 | M33: Creux + Cheminée | N33: 301.31
A34: Marseillan Ville | B34: Travée B | C34: 2 | D34: B2-3 | E34: 542 | J34: 128 | K34: =LOOKUP($E34-$J34,'455 hL comp haut'!$A$2:$A$544,'455 hL comp haut'!$D$2:$D$544) -> 405.73 | L34: 455 | M34: Creux + Cheminée | N34: 461.42
A35: Marseillan Ville | B35: Travée B | C35: 2 | D35: B2-4 | E35: 542 | J35: 278 | K35: =LOOKUP($E35-$J35,'455 hL comp haut'!$A$2:$A$544,'455 hL comp haut'!$D$2:$D$544) -> 266.51 | L35: 455 | M35: Creux + Cheminée | N35: 461.42
A36: Marseillan Ville | B36: Travée B | C36: 2 | D36: B2-5 | E36: 542 | J36: 175 | K36: =LOOKUP($E36-$J36,'625 hL comp haut'!$A$2:$A$544,'625 hL comp haut'!$D$2:$D$544) -> 495.5 | L36: 625 | M36: Creux + Cheminée | N36: 633.05
A37: Marseillan Ville | B37: Travée B | C37: 2 | D37: B2-6 | E37: 542 | J37: 68 | K37: =LOOKUP($E37-$J37,'625 hL comp haut'!$A$2:$A$544,'625 hL comp haut'!$D$2:$D$544) -> 624.07 | L37: 625 | M37: Creux + Cheminée | N37: 633.05
A38: Marseillan Ville | B38: Travée B | C38: 2 | D38: B2-7 | E38: 251 | J38: 63 | K38: =LOOKUP($E38-$J38,'335 hL comp haut'!$A$2:$A$253,'335 hL comp haut'!$D$2:$D$253) -> 333.73 | L38: 335 | M38: Creux + Cheminée | N38: 345
A39: Marseillan Ville | B39: Travée B | C39: 2 | D39: B2-8 | E39: 251 | J39: 84 | K39: =LOOKUP($E39-$J39,'335 hL comp haut'!$A$2:$A$253,'335 hL comp haut'!$D$2:$D$253) -> 309.95 | L39: 335 | M39: Creux + Cheminée | N39: 345
A40: Marseillan Ville | B40: Travée C | C40: 1 | D40: C1-0 | E40: 520 | G40: =L40/E40 -> 1.6346154 | H40: 60 | J40: 430 | K40: =IF(J40<60,"",(H40+E40-J40)*G40) -> 245.19231 | L40: 850 | M40: Creux + Cheminée | N40: 850
...

Sheet Barriques
A1: Liste des tonneliers
A3: 01 | B3: Gauthier
A4: 02 | B4: Mercurey
A5: 03 | B5: Ermitage
A6: 04 | B6: Vernou
A7: 05 | B7: Orion
A8: 06 | B8: Radoux
A9: 07 | B9: Damy
A10: 08 | B10: Saury
A11: 09 | B11: Seguin-Moreau
A12: 10 | B12: Ana Sélection
A13: 11 | B13: Nadalié

Sheet Feuil1
A1: =PI() -> 3.1415927 | B1: Pi | E1: G1-1 | Y1: h | Z1: V | AA1: h pris par le haut
Y2: 1117 | Z2: 1011.6757 | AA2: 0
Y3: 1116 | Z3: 1011.6757 | AA3: 1
Y4: 1115 | Z4: 1011.6757 | AA4: 2
Y5: 1114 | Z5: 1011.6757 | AA5: 3
Y6: 1113 | Z6: 1011.6757 | AA6: 4
Y7: 1112 | Z7: 1011.6757 | AA7: 5
Y8: 1111 | Z8: 1011.6757 | AA8: 6
Y9: 1110 | Z9: 1011.6757 | AA9: 7
Y10: 1109 | Z10: 1011.6757 | AA10: 8
Y11: 1108 | Z11: 1011.6757 | AA11: 9
Y12: 1107 | Z12: 1011.6757 | AA12: 10
Y13: 1106 | Z13: 1011.6757 | AA13: 11
... Y23: 1096 | Z23: 1011.6757 | AA23: 21
Y24: 1095 | Z24: =U58+$L$58+$H$68 -> 1011.6757 | AA24: 22
Y25: 1094 | Z25: =U59+$L$58+$H$68 -> 1010.6799 | AA25: 23
Y26: 1093 | Z26: =U60+$L$58+$H$68 -> 1009.7168 | AA26: 24
Y27: 1092 | Z27: =U61+$L$58+$H$68 -> 1008.7859 | AA27: 25
Y28: 1091 | Z28: =U62+$L$58+$H$68 -> 1007.8864 | AA28: 26
Y29: 1090 | Z29: =U63+$L$58+$H$68 -> 1007.018 | AA29: 27
Y30: 1089 | Z30: =U64+$L$58+$H$68 -> 1006.1801 | AA30: 28
Y31: 1088 | Z31: =U65+$L$58+$H$68 -> 1005.3721 | AA31: 29
Y32: 1087 | Z32: =U66+$L$58+$H$68 -> 1004.5934 | AA32: 30
Y33: 1086 | Z33: =U67+$L$58+$H$68 -> 1003.8436 | AA33: 31
Y34: 1085 | Z34: =U68+$L$58+$H$68 -> 1003.1221 | AA34: 32
Y35: 1084 | Z35: =U69+$L$58+$H$68 -> 1002.4283 | AA35: 33
... Y48: 1071 | Z48: =U82+$L$58+$H$68 -> 995.68673 | AA48: 46
K49: 950 | Y49: 1070 | Z49: =U83+$L$58+$H$68 -> 995.3243 | AA49: 47
K50: volume Cylindre | L50: hL | Y50: 1069 | Z50: =U84+$L$58+$H$68 -> 994.98145 | AA50: 48
K51: =K49*$A$1*B52^2 -> 96161756 | L51: =K51/100000 -> 961.61756 | Y51: 1068 | Z51: =U85+$L$58+$H$68 -> 994.65764 | AA51: 49
A52: Rayon | B52: =359/2 -> 179.5 | E52: =B54^2+B52^2 -> 39276.25 | Y52: 1067 | Z52: =U86+$L$58+$H$68 -> 994.35233 | AA52: 50
A53: V cone bas | B53: =($A$1*B52^2*B54)/3 -> 2834241.2 | D53: longueur hypothénus | E53: =SQRT(E52) -> 198.18237 | O53: h | P53: 61 | T53: =P53^2+B52^2 -> 35941.25 | V53: h total | W53: =$B$54+$K$49+$P$53 -> 1095 | Y53: 1066 | Z53: =U87+$L$58+$H$68 -> 994.06497 | AA53: 51
A54: h cone bas | B54: 84 | D54: tangente angle b | E54: =(B54/B52) -> 0.46796657 | O54: V cône haut | P54: =($P$53*$A$1*B52^2)/3 -> 2058199 | S54: longueur hypothénus | T54: =SQRT(T53) -> 189.58178 | Y54: 1065 | Z54: =U88+$L$58+$H$68 -> 993.79503 | AA54: 52
A55: V cone bas hL | B55: =B53/100000 -> 28.342412 | D55: tangente angle c | E55: =B52/B54 -> 2.1369048 | O55: hL | P55: =P54/100000 -> 20.58199 | S55: tangente angle b | T55: =(P53/B52) -> 0.33983287 | Y55: 1064 | Z55: =U89+$L$58+$H$68 -> 993.54195 | AA55: 53
S56: tangente angle c | T56: =B52/P53 -> 2.942623 | Y56: 1063 | Z56: =U90+$L$58+$H$68 -> 993.30519 | AA56: 54
C57: h | D57: R | F57: Volume des cônes | G57: hL | H57: fois 1,04 pour les 2 hL restant | K57: Cylindre | L57: hL | R57: h | S57: R | T57: V | U57: hL | Y57: 1062 | Z57: =U91+$L$58+$H$68 -> 993.08421 | AA57: 55
A58: =B55 -> 28.342412 | D58: =C58/$E$54 -> 0 | F58: =($A$1*D58^2*C58)/3 -> 0 | G58: =F58/100000 -> 0 | H58: =G58*1.04 -> 0 | J58: 950 | K58: =$A$1*J58*$B$52^2 -> 96161756 | L58: =K58/100000 -> 961.61756 | R58: 61 | S58: =R58/$T$55 -> 179.5 | T58: =(R58*$A$1*S58^2)/3 -> 2058199 | U58: =T58/100000 -> 20.58199 | Y58: 1061 | Z58: =U92+$L$58+$H$68 -> 992.87846 | AA58: 56
A59: 47 | D59: =C59/$E$54 -> 0 | F59: =($A$1*D59^2*C59)/3 -> 0 | G59: =F59/100000 -> 0 | H59: =G59*1.04 -> 0 | J59: 949 | K59: =$A$1*J59*$B$52^2 -> 96060533 | L59: =K59/100000 -> 960.60533 | R59: 60 | S59: =R59/$T$55 -> 176.55738 | T59: =(R59*$A$1*S59^2)/3 -> 1958626.4 | U59: =T59/100000 -> 19.586264 | Y59: 1060 | Z59: =U93+$L$58+$H$68 -> 992.68741 | AA59: 57
A60: 46 | D60: =C60/$E$54 -> 0 | F60: =($A$1*D60^2*C60)/3 -> 0 | G60: =F60/100000 -> 0 | H60: =G60*1.04 -> 0 | J60: 948 | K60: =$A$1*J60*$B$52^2 -> 95959310 | L60: =K60/100000 -> 959.5931 | R60: 59 | S60: =R60/$T$55 -> 173.61475 | T60: =(R60*$A$1*S60^2)/3 -> 1862318.2 | U60: =T60/100000 -> 18.623182 | Y60: 1059 | Z60: =U94+$L$58+$H$68 -> 992.5105 | AA60: 58
A61: 45 | D61: =C61/$E$54 -> 0 | F61: =($A$1*D61^2*C61)/3 -> 0 | G61: =F61/100000 -> 0 | H61: =G61*1.04 -> 0 | J61: 947 | K61: =$A$1*J61*$B$52^2 -> 95858087 | L61: =K61/100000 -> 958.58087 | R61: 58 | S61: =R61/$T$55 -> 170.67213 | T61: =(R61*$A$1*S61^2)/3 -> 1769220 | U61: =T61/100000 -> 17.6922 | Y61: 1058 | Z61: =U95+$L$58+$H$68 -> 992.34719 | AA61: 59
...
